Traceback (most recent call last):
  File "/Users/witoldtenhove/opt/anaconda3/envs/tensorflow/lib/python3.7/site-packages/jupyter_cache/executors/utils.py", line 56, in single_nb_execution
    record_timing=False,
  File "/Users/witoldtenhove/opt/anaconda3/envs/tensorflow/lib/python3.7/site-packages/nbclient/client.py", line 1112, in execute
    return NotebookClient(nb=nb, resources=resources, km=km, **kwargs).execute()
  File "/Users/witoldtenhove/opt/anaconda3/envs/tensorflow/lib/python3.7/site-packages/nbclient/util.py", line 74, in wrapped
    return just_run(coro(*args, **kwargs))
  File "/Users/witoldtenhove/opt/anaconda3/envs/tensorflow/lib/python3.7/site-packages/nbclient/util.py", line 53, in just_run
    return loop.run_until_complete(coro)
  File "/Users/witoldtenhove/opt/anaconda3/envs/tensorflow/lib/python3.7/asyncio/base_events.py", line 587, in run_until_complete
    return future.result()
  File "/Users/witoldtenhove/opt/anaconda3/envs/tensorflow/lib/python3.7/site-packages/nbclient/client.py", line 554, in async_execute
    cell, index, execution_count=self.code_cells_executed + 1
  File "/Users/witoldtenhove/opt/anaconda3/envs/tensorflow/lib/python3.7/site-packages/nbclient/client.py", line 857, in async_execute_cell
    self._check_raise_for_error(cell, exec_reply)
  File "/Users/witoldtenhove/opt/anaconda3/envs/tensorflow/lib/python3.7/site-packages/nbclient/client.py", line 760, in _check_raise_for_error
    raise CellExecutionError.from_cell_and_msg(cell, exec_reply_content)
nbclient.exceptions.CellExecutionError: An error occurred while executing the following cell:
------------------
# Load the model
model = tensorflow.keras.models.load_model('models/keras_model.h5')
------------------

[0;31m---------------------------------------------------------------------------[0m
[0;31mOSError[0m                                   Traceback (most recent call last)
[0;32m<ipython-input-4-531b81a68476>[0m in [0;36m<module>[0;34m[0m
[1;32m      1[0m [0;31m# Load the model[0m[0;34m[0m[0;34m[0m[0;34m[0m[0m
[0;32m----> 2[0;31m [0mmodel[0m [0;34m=[0m [0mtensorflow[0m[0;34m.[0m[0mkeras[0m[0;34m.[0m[0mmodels[0m[0;34m.[0m[0mload_model[0m[0;34m([0m[0;34m'models/keras_model.h5'[0m[0;34m)[0m[0;34m[0m[0;34m[0m[0m
[0m
[0;32m~/opt/anaconda3/envs/tensorflow/lib/python3.7/site-packages/tensorflow/python/keras/saving/save.py[0m in [0;36mload_model[0;34m(filepath, custom_objects, compile, options)[0m
[1;32m    204[0m         [0mfilepath[0m [0;34m=[0m [0mpath_to_string[0m[0;34m([0m[0mfilepath[0m[0;34m)[0m[0;34m[0m[0;34m[0m[0m
[1;32m    205[0m         [0;32mif[0m [0misinstance[0m[0;34m([0m[0mfilepath[0m[0;34m,[0m [0mstr[0m[0;34m)[0m[0;34m:[0m[0;34m[0m[0;34m[0m[0m
[0;32m--> 206[0;31m           [0;32mreturn[0m [0msaved_model_load[0m[0;34m.[0m[0mload[0m[0;34m([0m[0mfilepath[0m[0;34m,[0m [0mcompile[0m[0;34m,[0m [0moptions[0m[0;34m)[0m[0;34m[0m[0;34m[0m[0m
[0m[1;32m    207[0m [0;34m[0m[0m
[1;32m    208[0m   raise IOError(

[0;32m~/opt/anaconda3/envs/tensorflow/lib/python3.7/site-packages/tensorflow/python/keras/saving/saved_model/load.py[0m in [0;36mload[0;34m(path, compile, options)[0m
[1;32m    119[0m   [0;31m# Look for metadata file or parse the SavedModel[0m[0;34m[0m[0;34m[0m[0;34m[0m[0m
[1;32m    120[0m   [0mmetadata[0m [0;34m=[0m [0msaved_metadata_pb2[0m[0;34m.[0m[0mSavedMetadata[0m[0;34m([0m[0;34m)[0m[0;34m[0m[0;34m[0m[0m
[0;32m--> 121[0;31m   [0mmeta_graph_def[0m [0;34m=[0m [0mloader_impl[0m[0;34m.[0m[0mparse_saved_model[0m[0;34m([0m[0mpath[0m[0;34m)[0m[0;34m.[0m[0mmeta_graphs[0m[0;34m[[0m[0;36m0[0m[0;34m][0m[0;34m[0m[0;34m[0m[0m
[0m[1;32m    122[0m   [0mobject_graph_def[0m [0;34m=[0m [0mmeta_graph_def[0m[0;34m.[0m[0mobject_graph_def[0m[0;34m[0m[0;34m[0m[0m
[1;32m    123[0m   [0mpath_to_metadata_pb[0m [0;34m=[0m [0mos[0m[0;34m.[0m[0mpath[0m[0;34m.[0m[0mjoin[0m[0;34m([0m[0mpath[0m[0;34m,[0m [0mconstants[0m[0;34m.[0m[0mSAVED_METADATA_PATH[0m[0;34m)[0m[0;34m[0m[0;34m[0m[0m

[0;32m~/opt/anaconda3/envs/tensorflow/lib/python3.7/site-packages/tensorflow/python/saved_model/loader_impl.py[0m in [0;36mparse_saved_model[0;34m(export_dir)[0m
[1;32m    114[0m         [0;34m"SavedModel file does not exist at: %s%s{%s|%s}"[0m [0;34m%[0m[0;34m[0m[0;34m[0m[0m
[1;32m    115[0m         (export_dir, os.path.sep, constants.SAVED_MODEL_FILENAME_PBTXT,
[0;32m--> 116[0;31m          constants.SAVED_MODEL_FILENAME_PB))
[0m[1;32m    117[0m [0;34m[0m[0m
[1;32m    118[0m [0;34m[0m[0m

[0;31mOSError[0m: SavedModel file does not exist at: models/keras_model.h5/{saved_model.pbtxt|saved_model.pb}
OSError: SavedModel file does not exist at: models/keras_model.h5/{saved_model.pbtxt|saved_model.pb}

